Workbook

Sheet Events
A1: Description | B1: Date | C1: Source URL | D1: Time | E1: Location | F1: Association 1 | G1: Association 2 | H1: Source | I1: Comments
A2: The Honduran Government, led by President Porfirio Lobo Sosa, enacts a new General Mining Law, lifting a seven-year moratorium on new mining concessions. The General Mining Law is criticised by the Honduran National Coalition of Environmental Networks (CONROA) for failing to prohibit open pit mining, adequately protect community water sources, foster adequate consultation prior to concessions being granted, and for a lack of transparency regarding the financial and technical aspects of mining projects. | B2: 41297 | C2: https://legalculturessubsoil.ilcs.sas.ac.uk/legal-actions/1998-2013-honduran-mining-laws/#:~:text=In%202013%2C%20the%20Honduran%20Government%20(led%20by,the%20above%20moratorium%20on%20new%20mining%20concessions. | E2: Ministerio Público, Tegucigalpa | F2: n1 | G2: c1 | H2: src1
A3: The Honduran government enacts Decree 252-2013, which reduces the extent of the protected area of the Carlos Escaleras Mejia National Park by 217 hectares. The Carlos Escaleras Mejia National Park national park is named after Carlos Escaleras Mejía, a Honduran environmental activist and progressive politician who was assassinated on 18 October 1997. | B3: 41631 | C3: https://legalculturessubsoil.ilcs.sas.ac.uk/legal-actions/2012-2013-creation-and-reconfiguration-of-montana-de-botaderos-national-park/ | E3: ASP Mining Concession, Montaña de Botaderos National Park | F3: n1 | G3: c1 | H3: src2
A4: The Honduran government grants Inversiones Los Pinares (then known as EMCO Mining Company) a ten-year license to exploit iron oxide deposits at two concessions within the Carlos Escaleras Mejia National Park. Both sites, known as ASP and ASP2, fall within the pre-Decree 252-2013 protected areas of the national park. A later investigation by Contracorriente revealed collusion between Lenir Pérez (the owner of Los Pinares) and the state in the establishment of these mining concessions, with Pérez admitting in an email: “The park had been declared a national park 12 months earlier and we brought all the actors together and asked them to reconsider.” | B4: 41667 | C4: https://pbicanada.org/2024/01/26/pbi-honduras-visits-communities-in-tocoa-as-the-los-pinares-asp-mining-concession-is-set-to-expire-on-january-28/ | E4: ASP Mining Concession, Montaña de Botaderos National Park | F4: n1 | G4: c6 | H4: src3
A5: Inversiones ECOTEK (part of EMCO Group) obtains a provisional licence to construct an iron pelletizing plant at a site in Tocoa in direct proximity to the river Guapinol. Shortly after, construction begins on an access road connecting the planned mine site to the pelletizing plant. | B5: 43132 | C5: https://legalculturessubsoil.ilcs.sas.ac.uk/wp-content/uploads/2023/08/07-ASP-1-Y-2-eng-03.pdf#:~:text=submits%20requests%20for%20ASP1%20and%20ASP2%20non%2Dmetallic,MiAmbiente+%20grants%20environmental%20permit%20for%20ASP%20project. | E5: ECOTEK Processing Plant, Tocoa | F5: n1 | G5: c6 | H5: src4
A6: Guapinol residents begin sharing photos on social media showing the Guapinol river appearing chocolate brown and thick with muddy sediment. Locals attribute this to the construction of the access road to the mining concession, which they suggest is causing heavy sediment to contaminate the water of the Guapinol and San Pedro Rivers. | B6: 43216 | C6: https://www.facebook.com/photo/?fbid=811035502617239&set=pb.100083594761446.-2207520000 | E6: Rio Guapinol, Guapinol | F6: n1 | G6: c7 | H6: src5
A7: Residents organise an urgent community meeting to discuss the mining project. | B7: 43227 | C7: https://www.facebook.com/photo/?fbid=811065409280915&set=pb.100083594761446.-2207520000 | E7: Centro Basico, Guapinol | F7: n2 | G7: c2 | H7: src6
A8: Three days after an initial community meeting, residents organise a peaceful demonstration outside Caja Rural, Guapinol, the site of a meeting between Los Pinares and the Chief Inspector of Drinking Water. | B8: 43230 | C8: https://www.facebook.com/810956912625098/photos/pb.100083594761446.-2207520000/811064855947637/?type=3 | E8: Caja Rural, Guapinol | F8: n2 | G8: c2 | H8: src7
A9: Residents circulate further images of the contaminated river, as well as videos of contaminated tap water in homes in Guapinol. | B9: 43311 | C9: https://www.facebook.com/watch/?v=825384041182385 | E9: Rio Guapinol, Guapinol | F9: n1 | G9: c7 | H9: src8
A10: In protest of the ongoing mining activity, Guapinol residents set up a camp - commonly known as the ‘Guapinol Encampment in Defence of Water and Life' - on the access road​ to the mine. | B10: 43313 | C10: https://www.facebook.com/810956912625098/photos/pb.100083594761446.-2207520000/828000254254097/?type=3 | E10: Guapinol Encampment in Defence of Water and Life | F10: n2 | G10: c2 | H10: src9
A11: During a dispute between the residents of the camp and Inversiones Los Pinares staff and contracted security personnel, a security official shoots and wounds community member Rigoberto Bonilla Hernández. In response, the director of security is detained by protesters and handed to police. A vehicle and two containers belonging to Inversiones Los Pinares are allegedly set alight during the dispute. | B11: 43350 | C11: https://legalculturessubsoil.ilcs.sas.ac.uk/wp-content/uploads/2024/02/English-UVA-Report-on-Guapinol_0.pdf | E11: Guapinol Encampment in Defence of Water and Life | F11: n3 | G11: c3 | H11: src10
A12: The prosecutor’s office issued arrest warrants, approved by a National Jurisdiction judge in San Pedro Sula, for the arrest of eighteen community members. The defendants were charged with trespassing (or “unlawful occupation”) and property damage. | B12: 43374 | C12: https://legalculturessubsoil.ilcs.sas.ac.uk/legal-actions/2018-2022-criminalisation-and-detention-of-cmdbcp-environmental-rights-defenders/ | E12: Juzgado de Jurisdicción Nacional, Tegucigalpa | F12: n4 | G12: c4 | H12: src11
A13: On the basis of a judicial eviction order at least 1,200 police and army personnel, including a specialist militarised police unit known as ‘TIGRE’, are deployed to evict the encampment. Witnesses report live rounds and tear gas being used, and protesters being beaten. The altercation results in the death of two military personnel and one community member, with over a dozen individuals wounded. | B13: 43400 | C13: https://legalculturessubsoil.ilcs.sas.ac.uk/legal-actions/2018-eviction-of-protest-encampment/ | E13: Guapinol Encampment in Defence of Water and Life | F13: n3 | G13: c3 | H13: src12
A14: Thirteen community members voluntarily appear before a court in La Ceiba, where they learn of a second arrest warrant accusing 31 community members of unjust deprivation of liberty, aggravated arson, theft, and unlawful association in relation to the events that took place 7 September 2018. They are subsequently held in pretrial detention in Tegucigalpa. | B14: 43517 | C14: https://legalculturessubsoil.ilcs.sas.ac.uk/legal-actions/2018-2022-criminalisation-and-detention-of-cmdbcp-environmental-rights-defenders/ | E14: Edificio Judicial de La Ceiba, La Ceiba | F14: n4 | G14: c4 | H14: src13
A15: Members of the Municipal Committee for the Defense of Common and Public Goods (CMDBCP), the San Alonso Rodríguez Foundation, and the Coalition Against Impunity, file a constitutional challenge against Decree 252-2013. | B15: 43521 | C15: https://legalculturessubsoil.ilcs.sas.ac.uk/legal-actions/2019-constitutional-challenge-to-decree-modifying-montana-de-botaderos-national-park/ | F15: n2 | G15: c2 | H15: src14
A16: A National Jurisdiction judge in Tegucigalpa dismisses the charges against the thirteen defenders during the initial hearings. The judge considered that the actions fell within the Honduran Secretary of Human Rights ’definition of a “socio-environmental conflict”, and decided that the protest was legitimate, given it was the only tool available for civil society actors to gain the attention of relevant State officials. | B16: 43526 | C16: https://legalculturessubsoil.ilcs.sas.ac.uk/wp-content/uploads/2024/02/English-UVA-Report-on-Guapinol_0.pdf | E16: Juzgado de Jurisdicción Nacional, Tegucigalpa | F16: n4 | G16: c4 | H16: src15
A17: The detainees are released. | B17: 43530 | C17: https://legalculturessubsoil.ilcs.sas.ac.uk/wp-content/uploads/2024/02/English-UVA-Report-on-Guapinol_0.pdf | E17: Juzgado de Jurisdicción Nacional, Tegucigalpa | F17: n4 | G17: c4 | H17: src16
A18: Seven additional community members voluntarily appear before a National Jurisdiction judge in Tegucigalpa to address charges from the second arrest warrant. They arrive carrying a casket representing an eighth community member, who is listed in the same charges despite being deceased. | B18: 43703 | C18: https://legalculturessubsoil.ilcs.sas.ac.uk/wp-content/uploads/2024/02/English-UVA-Report-on-Guapinol_0.pdf | E18: Juzgado de Jurisdicción Nacional, Tegucigalpa | F18: n4 | G18: c4 | H18: src17
A19: Roberto Antonio Argueta Tejada, one of 32 environmental defenders criminalised as part of the Guapinol case, is shot to death by several heavily armed strangers near the San Isidro hospital in Tocoa. | B19: 43705 | C19: https://legalculturessubsoil.ilcs.sas.ac.uk/wp-content/uploads/2024/02/English-UVA-Report-on-Guapinol_0.pdf | E19: Hospital San Isidro, Tocoa | F19: n3 | G19: c3 | H19: src18
A20: In Tegucigalpa, National Jurisdiction Judge Claudio Aguilar grants Arnold Javier Alemán a temporary dismissal on the charges of illegal trespass and damages, leaving the remainder of the charges intact. | B20: 43707 | C20: https://legalculturessubsoil.ilcs.sas.ac.uk/wp-content/uploads/2024/02/English-UVA-Report-on-Guapinol_0.pdf | E20: Juzgado de Jurisdicción Nacional, Tegucigalpa | F20: n4 | G20: c4 | H20: src19
A21: National Jurisdiction Judge Lizeth Vallecillo issues a ruling that links the nine environmental defenders to crimes of aggravated arson and unjust deprivation of liberty, while dismissing the crimes of illicit association and theft. They are subsequently placed in pretrial detention in Olanchito. | B21: 43709 | C21: https://legalculturessubsoil.ilcs.sas.ac.uk/wp-content/uploads/2024/02/English-UVA-Report-on-Guapinol_0.pdf | E21: Tocoa | F21: n4 | G21: c4 | H21: src20
A22: The National Jurisdiction Court of Appeals rejects a habeas corpus petition filed by the defence attorney. In response, prominent international advocacy organizations, including the Due Process of Law Foundation (DPLF), Human Rights Research and Education Centre, and the Collective Corporation of Lawyers “José Alvear Restrepo” filed a joint amicus brief echoing the defense attorneys ’previously expressed concerns and asserting that the community leaders ’detention was in violation of both domestic and international law. | B22: 43733 | C22: https://legalculturessubsoil.ilcs.sas.ac.uk/wp-content/uploads/2024/02/English-UVA-Report-on-Guapinol_0.pdf | E22: Juzgado de Jurisdicción Nacional, Tegucigalpa | F22: n4 | G22: c4 | H22: src21
A23: Following another hearing, the decision is made to extend the pretrial detention of the Guapinol activists. | B23: 43775 | C23: https://legalculturessubsoil.ilcs.sas.ac.uk/wp-content/uploads/2024/02/English-UVA-Report-on-Guapinol_0.pdf | E23: Centro Penal, Olanchito | F23: n4 | G23: c4 | H23: src22
A24: A series of break-ins are reported at the Tocoa office of the Coordinadora de Organizaciones Populares del Aguán (COPA), a conglomerate of organisations defending human, enviornmental, and social rights in the Aguan Valley Region. Unidentified individuals stole a computer and printer and ransacked drawers filled with documents. COPA member Carlos Leonel George reported the incident to the police. Rather than investigate the break-ins, the police arrest Carlos, who was one of the twelve Guapinol community members who voluntarily went to court in February 2019, only to have all the charges subsequently dismissed. | B24: 43800 | C24: https://legalculturessubsoil.ilcs.sas.ac.uk/wp-content/uploads/2024/02/English-UVA-Report-on-Guapinol_0.pdf | E24: Tocoa | F24: n3 | G24: c3 | H24: src23
A25: The Center for International Justice and Law (CEJIL) submits an amicus brief to the National Jurisdiction Court of Appeals. | B25: 43888 | C25: https://legalculturessubsoil.ilcs.sas.ac.uk/wp-content/uploads/2024/02/English-UVA-Report-on-Guapinol_0.pdf | F25: n4 | G25: c5 | H25: src24
A26: A group of civil society organizations, including the National Committee against Torture and Cruel, Inhumane, and Degrading Treatment (MNP-CONAPREV) and the Committee for Family of the Detained and Disappeared (COFADEH), amongst others, file a second habeas corpus petition with the Supreme Court of Honduras. | B26: 43914 | C26: https://legalculturessubsoil.ilcs.sas.ac.uk/wp-content/uploads/2024/02/English-UVA-Report-on-Guapinol_0.pdf | F26: n4 | G26: c5 | H26: src25
A27: In Tegucigalpa, the National Jurisdiction Court of Appeals a dismissal previously issued in favour of human rights defenders Juan Antonio López, Carlos Leonel George, Reinaldo Domínguez, José Adalid Cedillo and Marco Tulio Ramos. | B27: 44056 | C27: https://www.amnesty.org/es/wp-content/uploads/2021/05/AMR3729342020ENGLISH.pdf | E27: Juzgado de Jurisdicción Nacional, Tegucigalpa | F27: n4 | G27: c4 | H27: src26
A28: The Honduran Human Rights Ombudsperson writes a public letter directed at the judicial authorities which describes the detained members of the CMDBCP as human rights activists engaged in legitimate protest activities. | B28: 44096 | C28: https://legalculturessubsoil.ilcs.sas.ac.uk/wp-content/uploads/2024/02/English-UVA-Report-on-Guapinol_0.pdf | F28: n4 | G28: c5 | H28: src27
A29: Joaquin Morazan Erazo, named in the 2018 arrest warrant, is shot and killed at his home in Tocoa, Colon. | B29: 44117 | C29: https://www.frontlinedefenders.org/en/case/killing-defender-arnold-joaquin-morazan-erazo-who-had-been-criminalised-his-defense-river | E29: Tocoa | F29: n3 | G29: c3 | H29: src28
A30: The Office of the United Nations High Commissioner for Human Rights (UN OHCHR) issues a country report raising concerns about the misuse of the judicial system in the Guapinol case. | B30: 44252 | C30: https://legalculturessubsoil.ilcs.sas.ac.uk/legal-actions/2021-un-high-commissioner-for-human-rights-report-to-the-human-rights-council-on-honduras/ | F30: n4 | G30: c5 | H30: src29
A31: The UN Working Group on Arbitrary Detention declares the Guapinol Eight - Porfirio Sorto Cedillo, José Abelino Cedillo, Kelvin Alejandro Romero, Arnol Javier Alemán, Ever Alexander Cedillo, Orbin Nahún Hernández, and Daniel Márquez - to be arbitrarily detained and calls for their release. | B31: 44258 | C31: https://legalculturessubsoil.ilcs.sas.ac.uk/legal-actions/2021-un-working-group-on-arbitrary-detention-issued-opinion-on-detained-cmdbcp-environmental-defenders/ | F31: n4 | G31: c5 | H31: src30
A32: Members of the CMDBPC present an environmental report to the Secretariat of Natural Resources and Environment containing evidence that mining activity and related road infrastructure in the Carlos Escaleras Mejia National Park has negatively impacted 35 micro-basins of the Guapinol and San Pedro rivers. | B32: 44374 | C32: https://criterio.hn/presentan-informe-sobre-contaminacion-provocada-por-minera-en-el-rio-guapinol-en-tocoa-colon/ | E32: ASP Mining Concession, Montaña de Botaderos National Park | F32: n2 | G32: c7 | H32: src52
A33: The preventive detention of the Guapinol Eight is extended for an six additional months. | B33: 44434 | C33: https://protectdefenders.eu/honduras-trial-of-the-guapinol-defenders-and-harassment-against-their-families/ | E33: Centro Penal, Olanchito | F33: n4 | G33: c4 | H33: src31
A34: The trial against the Guapinol Eight begins after over two years of pre-trial detention. | B34: 44531 | C34: https://www.amnesty.org/en/latest/news/2021/12/honduras-amnesty-international-urges-authorities-immediately-release-eight-prisoners-conscience/ | E34: Juzgado de Letra, Trujillo | F34: n4 | G34: c4 | H34: src32
A35: Amnesty International writes an open letter expressing concerns about irregularities in the prosecution of the Guapinol Eight and describing those standing trial as 'victims of arbitrary detention and unfounded criminal prosecution stemming solely from their human rights work.' | B35: 44541 | C35: https://www.amnesty.org/en/latest/news/2022/02/honduras-amnesty-international-demands-justice-guapinol-eight/ | F35: n4 | G35: c5 | H35: src33
A36: A court in Trujillo finds six of the Guapinol Eight guilty of several charges including illegal deprivation of liberty and aggravated damages against a contractor of Inversiones Los Pinares, and aggravated damages against the company itself. | B36: 44601 | C36: https://www.amnesty.org/en/latest/news/2022/02/honduras-amnesty-international-condemns-conviction-six-guapinol-eight/ | E36: Juzgado de Letra, Trujillo | F36: n4 | G36: c4 | H36: src34
A37: One day after the sentencing, the Supreme Court declares a mistrial and grants injunctions in favour of the Guapinol Eight. | B37: 44602 | C37: https://www.frontlinedefenders.org/en/statement-report/international-forum-calls-immediate-release-and-reparations-defenders-guapinol | E37: Corte Suprema de Justicia, Tegucigalpa | F37: n4 | G37: c4 | H37: src35
A38: Environmental rights defenders José Daniel Márquez, José Abelino Cedillo, Ewer Cedillo, Kelvin Romero, Orbin Nahún Hernández and Porfirio Soto, are released on bail after 914 days spent in pre-trial detention. | B38: 44617 | C38: https://www.frontlinedefenders.org/en/case/legal-proceedings-reopened-against-five-environmental-defenders-guapinol-including-late-juan | E38: Centro Penal, Olanchito | F38: n4 | G38: c4 | H38: src36
A39: Members of the CMDBPC issue an urgent call to President Xiomara Castro in response to the intensification of threats, surveillance, and a social media smear campaign against the organisation following their accompaniment of the government on a fact-finding visit to the Carlos Escaleras National Park. | B39: 44875 | C39: https://criterio.hn/recuerdan-a-serna-que-sigue-pendiente-informe-por-contaminacion-de-parque-nacional-carlos-escaleras/ | E39: ASP Mining Concession, Montaña de Botaderos National Park | F39: n3 | G39: c3
A40: A technical report presented by the CMDBPC reveals a significant reduction of forest cover in concession and the adjacent areas. It documents how Los Pinares-ECTOEK cleared vegetation and topsoil in the ASP2 concession area to establish a waste dump without an environmental license, resulting in sediment and contaminated water being discharged into La Cascada ravine—a permanent water source and tributary of the San Pedro River, located within the core zone of the national park. | B40: 44905 | C40: https://contracorriente.red/en/2024/01/25/victims-of-mining-conflict-expect-an-indictment-against-lenir-perez-in-view-of-a-possible-concession-extension/ | E40: ASP Mining Concession, Montaña de Botaderos National Park | F40: n2 | G40: c7
...

Sheet Associations
A1: ID | B1: Description | C1: Mode | D1: Filter Path
A2: n1 | B2: Origins of the situation | C2: NARRATIVE
A3: n2 | B3: Community resistance to the Los Pinares-ECOTEK project | C3: NARRATIVE
A4: n3 | B4: The use of violence against the environmental defenders | C4: NARRATIVE
A5: n4 | B5: The criminalisation of environmental defenders | C5: NARRATIVE
A6: n5 | B6: The future of the Los Pinares-ECOTEK project | C6: NARRATIVE
A7: n6 | B7: Legal action against Los Pinares-ECOTEK and government officials | C7: NARRATIVE
A8: c1 | B8: Policy and regulatory changes | C8: CATEGORY
A9: c2 | B9: Peaceful protests and activism | C9: CATEGORY
A10: c3 | B10: Violence and conflict | C10: CATEGORY
A11: c4 | B11: Legal proceedings | C11: CATEGORY
A12: c5 | B12: National and international advocacy | C12: CATEGORY
A13: c6 | B13: Developments in the Los Pinares-ECOTEK project | C13: CATEGORY
A14: c7 | B14: Environmental impacts of the Los Pinares-ECOTEK project | C14: CATEGORY

Sheet Sources
A1: ID | B1: Title | C1: Thumbnail | D1: Description | E1: Path 1 | F1: Path 2 | G1: Path 3 | H1: Path 4 | I1: Type
A2: src1 | B2: Honduran Government Enacts New General Mining Law
A3: src2 | B3: Honduras Reduces Carlos Escaleras Mejía National Park Protected Area | E3: images/231213.png
A4: src3 | B4: Los Pinares Granted Mining License in National Park | E4: images/28012014.png
A5: src4 | B5: ECOTEK Obtains License for Iron Pelletizing Plant
A6: src5 | B6: Guapinol River Contamination Documented by Residents | E6: images/26042018.jpg | F6: images/26042018a.jpg | G6: images/26042018b.jpg | H6: images/26042018c.jpg
A7: src6 | B7: Community Meeting Organized to Discuss Mining Project | E7: images/07052018.jpg
A8: src7 | B8: Peaceful Demonstration at Caja Rural | E8: images/10052018.jpg | F8: images/10052018a.jpg | G8: images/10052018b.jpg
A9: src8 | B9: Further River Contamination Evidence Circulated | E9: images/30072018.jpg | F9: images/30072018a.mp4
A10: src9 | B10: Guapinol Encampment Established to Defend Water | E10: images/01082018.jpg | F10: images/01082018a.jpg | G10: images/01082018b.jpg
A11: src10 | B11: Security Official Shoots Protester During Dispute | E11: images/07092018.jpg
A12: src11 | B12: Arrest Warrants Issued for Eighteen Community Members
A13: src12 | B13: Police and Military Evict Encampment with Violence | E13: images/27102018.jpg | F13: images/27102018a.mp4
A14: src13 | B14: Thirteen Community Members Appear Before Court
A15: src14 | B15: Constitutional Challenge Filed Against Decree 252-2013
A16: src15 | B16: Charges Dismissed Against Thirteen Defenders
A17: src16 | B17: Detained Protesters Released | E17: images/06032019.jpg
A18: src17 | B18: Seven Additional Community Members Appear in Court | E18: images/26082019.mp4
A19: src18 | B19: Environmental Defender Roberto Argueta Assassinated | E19: images/28082019.jpg
A20: src19 | B20: Temporary Dismissal Granted to Arnold Alemán
A21: src20 | B21: Nine Environmental Defenders Placed in Pretrial Detention | E21: images/01092019.mp4
A22: src21 | B22: Court Rejects Habeas Corpus Petition
A23: src22 | B23: Pretrial Detention Extended for Guapinol Activists
A24: src23 | B24: Break-ins Reported at COPA Office
A25: src24 | B25: CEJIL Submits Amicus Brief to Court of Appeals
A26: src25 | B26: Second Habeas Corpus Petition Filed with Supreme Court
A27: src26 | B27: Court of Appeals Overturns Previous Dismissal
A28: src27 | B28: Human Rights Ombudsperson Defends CMDBCP Members
A29: src28 | B29: Joaquin Morazan Erazo Assassinated | E29: images/13102020.jpg
A30: src29 | B30: UN OHCHR Issues Report on Judicial System Misuse
A31: src30 | B31: UN Working Group Declares Guapinol Eight Arbitrarily Detained
A32: src31 | B32: Preventive Detention Extended for Guapinol Eight
A33: src32 | B33: Trial Against Guapinol Eight Begins After Two Years | E33: images/01122021.mp4
A34: src33 | B34: Amnesty International Expresses Concerns About Trial | E34: images/11122021.jpg
A35: src34 | B35: Court Finds Six Defendants Guilty of Multiple Crimes
A36: src35 | B36: Supreme Court Declares Mistrial and Grants Injunctions
A37: src36 | B37: Environmental Defenders Released on Bail After 914 Days | E37: images/25022022.jpg
A38: src37 | B38: Two Anti-Mining Activists Murdered in Guapinol | E38: images/07012023.jpg
A39: src38 | B39: Six Activists Face Possible Further Prosecution
A40: src39 | B40: Drones Reported Surveilling Activists' Homes | E40: images/21022023.jpg
...

Sheet Categories
A1: Title | B1: Description
A2: Policy and regulatory changes | B2: First category
A3: Peaceful protests and activism | B3: Second category
A4: Violence and conflict | B4: Third category
A5: Legal proceedings | B5: Fourth category
A6: National and international advocacy | B6: Fifth category
A7: Developments in the Los Pinares / ECOTEK project | B7: Sixth category
A8: Environmental impacts of the Los Pinares / ECOTEK project | B8: Seventh category

Sheet Sites
A1: Location | B1: Lat | D1: Comments
A2: Montaña de Botaderos National Park | B2: 15.431855 | C2: -86.144446
A3: ASP Mining Concession, Montaña de Botaderos National Park | B3: 15.474638 | C3: -85.93072
A4: ECOTEK Processing Plant, Tocoa | B4: 15.620373 | C4: -86.027341
A5: Rio Guapinol, Guapinol | B5: 15.618746 | C5: -86.030866
A6: Centro Basico, Guapinol | B6: 15.614502 | C6: -86.038829
A7: Caja Rural, Guapinol | B7: 15.615516 | C7: -86.035857
A8: Guapinol Encampment in Defence of Water and Life | B8: 15.616244 | C8: -86.016055
A9: Edificio Judicial de La Ceiba, La Ceiba | B9: 15.769586 | C9: -86.758224
A10: Juzgado de Jurisdicción Nacional, Tegucigalpa | B10: 14.102994 | C10: -87.187926
A11: Hospital San Isidro, Tocoa | B11: 15.662348 | C11: -86.001268
A12: Tocoa | B12: 15.657623 | C12: -85.997824
A13: Corte Suprema de Justicia, Tegucigalpa | B13: 14.072813 | C13: -87.200923
... A22: Juzgado de Letra, Trujillo | B22: 15.922509 | C22: -85.9461

Sheet EXPORT_EVENTS
A1: description | B1: date | C1: time | D1: location | E1: latitude | F1: longitude | G1: association1 | H1: association2 | I1: source1
A2: =Events!A2 -> The Honduran Government, led by President Porfirio Lobo Sosa, enacts a new General Mining Law, lifting a seven-year moratorium on new mining concessions. The General Mining Law is criticised by the Honduran National Coalition of Environmental Networks (CONROA) for failing to prohibit open pit mining, adequately protect community water sources, foster adequate consultation prior to concessions being granted, and for a lack of transparency regarding the financial and technical aspects of mining projects. | B2: =TEXT(Events!B2, "MM/DD/YYYY") -> 01/23/2013 | D2: =Events!E2 -> Ministerio Público, Tegucigalpa | G2: =IF(ISBLANK(Events!F2), "", Events!F2) -> n1 | H2: =IF(ISBLANK(Events!G2), "", Events!G2) -> c1 | I2: =IF(ISBLANK(Events!H2), "", Events!H2) -> src1
A3: =Events!A3 -> The Honduran government enacts Decree 252-2013, which reduces the extent of the protected area of the Carlos Escaleras Mejia National Park by 217 hectares. The Carlos Escaleras Mejia National Park national park is named after Carlos Escaleras Mejía, a Honduran environmental activist and progressive politician who was assassinated on 18 October 1997. | B3: =TEXT(Events!B3, "MM/DD/YYYY") -> 12/23/2013 | D3: =Events!E3 -> ASP Mining Concession, Montaña de Botaderos National Park | E3: 15.431855 | F3: -86.144446 | G3: =IF(ISBLANK(Events!F3), "", Events!F3) -> n1 | H3: =IF(ISBLANK(Events!G3), "", Events!G3) -> c1 | I3: =IF(ISBLANK(Events!H3), "", Events!H3) -> src2
A4: =Events!A4 -> The Honduran government grants Inversiones Los Pinares (then known as EMCO Mining Company) a ten-year license to exploit iron oxide deposits at two concessions within the Carlos Escaleras Mejia National Park. Both sites, known as ASP and ASP2, fall within the pre-Decree 252-2013 protected areas of the national park. A later investigation by Contracorriente revealed collusion between Lenir Pérez (the owner of Los Pinares) and the state in the establishment of these mining concessions, with Pérez admitting in an email: “The park had been declared a national park 12 months earlier and we brought all the actors together and asked them to reconsider.” | B4: =TEXT(Events!B4, "MM/DD/YYYY") -> 01/28/2014 | D4: =Events!E4 -> ASP Mining Concession, Montaña de Botaderos National Park | E4: 15.474638 | F4: -85.93072 | G4: =IF(ISBLANK(Events!F4), "", Events!F4) -> n1 | H4: =IF(ISBLANK(Events!G4), "", Events!G4) -> c6 | I4: =IF(ISBLANK(Events!H4), "", Events!H4) -> src3
A5: =Events!A5 -> Inversiones ECOTEK (part of EMCO Group) obtains a provisional licence to construct an iron pelletizing plant at a site in Tocoa in direct proximity to the river Guapinol. Shortly after, construction begins on an access road connecting the planned mine site to the pelletizing plant. | B5: =TEXT(Events!B5, "MM/DD/YYYY") -> 02/01/2018 | D5: =Events!E5 -> ECOTEK Processing Plant, Tocoa | E5: 15.620373 | F5: -86.027341 | G5: =IF(ISBLANK(Events!F5), "", Events!F5) -> n1 | H5: =IF(ISBLANK(Events!G5), "", Events!G5) -> c6 | I5: =IF(ISBLANK(Events!H5), "", Events!H5) -> src4
A6: =Events!A6 -> Guapinol residents begin sharing photos on social media showing the Guapinol river appearing chocolate brown and thick with muddy sediment. Locals attribute this to the construction of the access road to the mining concession, which they suggest is causing heavy sediment to contaminate the water of the Guapinol and San Pedro Rivers. | B6: =TEXT(Events!B6, "MM/DD/YYYY") -> 04/26/2018 | D6: =Events!E6 -> Rio Guapinol, Guapinol | E6: 15.618746 | F6: -86.030866 | G6: =IF(ISBLANK(Events!F6), "", Events!F6) -> n1 | H6: =IF(ISBLANK(Events!G6), "", Events!G6) -> c7 | I6: =IF(ISBLANK(Events!H6), "", Events!H6) -> src5
A7: =Events!A7 -> Residents organise an urgent community meeting to discuss the mining project. | B7: =TEXT(Events!B7, "MM/DD/YYYY") -> 05/07/2018 | D7: =Events!E7 -> Centro Basico, Guapinol | E7: 15.614502 | F7: -86.038829 | G7: =IF(ISBLANK(Events!F7), "", Events!F7) -> n2 | H7: =IF(ISBLANK(Events!G7), "", Events!G7) -> c2 | I7: =IF(ISBLANK(Events!H7), "", Events!H7) -> src6
A8: =Events!A8 -> Three days after an initial community meeting, residents organise a peaceful demonstration outside Caja Rural, Guapinol, the site of a meeting between Los Pinares and the Chief Inspector of Drinking Water. | B8: =TEXT(Events!B8, "MM/DD/YYYY") -> 05/10/2018 | D8: =Events!E8 -> Caja Rural, Guapinol | E8: 15.615516 | F8: -86.035857 | G8: =IF(ISBLANK(Events!F8), "", Events!F8) -> n2 | H8: =IF(ISBLANK(Events!G8), "", Events!G8) -> c2 | I8: =IF(ISBLANK(Events!H8), "", Events!H8) -> src7
A9: =Events!A9 -> Residents circulate further images of the contaminated river, as well as videos of contaminated tap water in homes in Guapinol. | B9: =TEXT(Events!B9, "MM/DD/YYYY") -> 07/30/2018 | D9: =Events!E9 -> Rio Guapinol, Guapinol | G9: =IF(ISBLANK(Events!F9), "", Events!F9) -> n1 | H9: =IF(ISBLANK(Events!G9), "", Events!G9) -> c7 | I9: =IF(ISBLANK(Events!H9), "", Events!H9) -> src8
A10: =Events!A10 -> In protest of the ongoing mining activity, Guapinol residents set up a camp - commonly known as the ‘Guapinol Encampment in Defence of Water and Life' - on the access road​ to the mine. | B10: =TEXT(Events!B10, "MM/DD/YYYY") -> 08/01/2018 | D10: =Events!E10 -> Guapinol Encampment in Defence of Water and Life | E10: 15.616244 | F10: -86.016055 | G10: =IF(ISBLANK(Events!F10), "", Events!F10) -> n2 | H10: =IF(ISBLANK(Events!G10), "", Events!G10) -> c2 | I10: =IF(ISBLANK(Events!H10), "", Events!H10) -> src9
A11: =Events!A11 -> During a dispute between the residents of the camp and Inversiones Los Pinares staff and contracted security personnel, a security official shoots and wounds community member Rigoberto Bonilla Hernández. In response, the director of security is detained by protesters and handed to police. A vehicle and two containers belonging to Inversiones Los Pinares are allegedly set alight during the dispute. | B11: =TEXT(Events!B11, "MM/DD/YYYY") -> 09/07/2018 | D11: =Events!E11 -> Guapinol Encampment in Defence of Water and Life | E11: 15.616244 | F11: -86.016055 | G11: =IF(ISBLANK(Events!F11), "", Events!F11) -> n3 | H11: =IF(ISBLANK(Events!G11), "", Events!G11) -> c3 | I11: =IF(ISBLANK(Events!H11), "", Events!H11) -> src10
A12: =Events!A12 -> The prosecutor’s office issued arrest warrants, approved by a National Jurisdiction judge in San Pedro Sula, for the arrest of eighteen community members. The defendants were charged with trespassing (or “unlawful occupation”) and property damage. | B12: =TEXT(Events!B12, "MM/DD/YYYY") -> 10/01/2018 | D12: =Events!E12 -> Juzgado de Jurisdicción Nacional, Tegucigalpa | G12: =IF(ISBLANK(Events!F12), "", Events!F12) -> n4 | H12: =IF(ISBLANK(Events!G12), "", Events!G12) -> c4 | I12: =IF(ISBLANK(Events!H12), "", Events!H12) -> src11
A13: =Events!A13 -> On the basis of a judicial eviction order at least 1,200 police and army personnel, including a specialist militarised police unit known as ‘TIGRE’, are deployed to evict the encampment. Witnesses report live rounds and tear gas being used, and protesters being beaten. The altercation results in the death of two military personnel and one community member, with over a dozen individuals wounded. | B13: =TEXT(Events!B13, "MM/DD/YYYY") -> 10/27/2018 | D13: =Events!E13 -> Guapinol Encampment in Defence of Water and Life | E13: 15.616244 | F13: -86.016055 | G13: =IF(ISBLANK(Events!F13), "", Events!F13) -> n3 | H13: =IF(ISBLANK(Events!G13), "", Events!G13) -> c3 | I13: =IF(ISBLANK(Events!H13), "", Events!H13) -> src12
A14: =Events!A14 -> Thirteen community members voluntarily appear before a court in La Ceiba, where they learn of a second arrest warrant accusing 31 community members of unjust deprivation of liberty, aggravated arson, theft, and unlawful association in relation to the events that took place 7 September 2018. They are subsequently held in pretrial detention in Tegucigalpa. | B14: =TEXT(Events!B14, "MM/DD/YYYY") -> 02/21/2019 | D14: =Events!E14 -> Edificio Judicial de La Ceiba, La Ceiba | E14: 15.769586 | F14: -86.758224 | G14: =IF(ISBLANK(Events!F14), "", Events!F14) -> n4 | H14: =IF(ISBLANK(Events!G14), "", Events!G14) -> c4 | I14: =IF(ISBLANK(Events!H14), "", Events!H14) -> src13
A15: =Events!A15 -> Members of the Municipal Committee for the Defense of Common and Public Goods (CMDBCP), the San Alonso Rodríguez Foundation, and the Coalition Against Impunity, file a constitutional challenge against Decree 252-2013. | B15: =TEXT(Events!B15, "MM/DD/YYYY") -> 02/25/2019 | D15: =Events!E15 | G15: =IF(ISBLANK(Events!F15), "", Events!F15) -> n2 | H15: =IF(ISBLANK(Events!G15), "", Events!G15) -> c2 | I15: =IF(ISBLANK(Events!H15), "", Events!H15) -> src14
A16: =Events!A16 -> A National Jurisdiction judge in Tegucigalpa dismisses the charges against the thirteen defenders during the initial hearings. The judge considered that the actions fell within the Honduran Secretary of Human Rights ’definition of a “socio-environmental conflict”, and decided that the protest was legitimate, given it was the only tool available for civil society actors to gain the attention of relevant State officials. | B16: =TEXT(Events!B16, "MM/DD/YYYY") -> 03/02/2019 | D16: =Events!E16 -> Juzgado de Jurisdicción Nacional, Tegucigalpa | E16: 14.102994 | F16: -87.187926 | G16: =IF(ISBLANK(Events!F16), "", Events!F16) -> n4 | H16: =IF(ISBLANK(Events!G16), "", Events!G16) -> c4 | I16: =IF(ISBLANK(Events!H16), "", Events!H16) -> src15
A17: =Events!A17 -> The detainees are released. | B17: =TEXT(Events!B17, "MM/DD/YYYY") -> 03/06/2019 | D17: =Events!E17 -> Juzgado de Jurisdicción Nacional, Tegucigalpa | G17: =IF(ISBLANK(Events!F17), "", Events!F17) -> n4 | H17: =IF(ISBLANK(Events!G17), "", Events!G17) -> c4 | I17: =IF(ISBLANK(Events!H17), "", Events!H17) -> src16
A18: =Events!A18 -> Seven additional community members voluntarily appear before a National Jurisdiction judge in Tegucigalpa to address charges from the second arrest warrant. They arrive carrying a casket representing an eighth community member, who is listed in the same charges despite being deceased. | B18: =TEXT(Events!B18, "MM/DD/YYYY") -> 08/26/2019 | D18: =Events!E18 -> Juzgado de Jurisdicción Nacional, Tegucigalpa | E18: 14.102994 | F18: -87.187926 | G18: =IF(ISBLANK(Events!F18), "", Events!F18) -> n4 | H18: =IF(ISBLANK(Events!G18), "", Events!G18) -> c4 | I18: =IF(ISBLANK(Events!H18), "", Events!H18) -> src17
A19: =Events!A19 -> Roberto Antonio Argueta Tejada, one of 32 environmental defenders criminalised as part of the Guapinol case, is shot to death by several heavily armed strangers near the San Isidro hospital in Tocoa. | B19: =TEXT(Events!B19, "MM/DD/YYYY") -> 08/28/2019 | D19: =Events!E19 -> Hospital San Isidro, Tocoa | E19: 15.662348 | F19: -86.001268 | G19: =IF(ISBLANK(Events!F19), "", Events!F19) -> n3 | H19: =IF(ISBLANK(Events!G19), "", Events!G19) -> c3 | I19: =IF(ISBLANK(Events!H19), "", Events!H19) -> src18
A20: =Events!A20 -> In Tegucigalpa, National Jurisdiction Judge Claudio Aguilar grants Arnold Javier Alemán a temporary dismissal on the charges of illegal trespass and damages, leaving the remainder of the charges intact. | B20: =TEXT(Events!B20, "MM/DD/YYYY") -> 08/30/2019 | D20: =Events!E20 -> Juzgado de Jurisdicción Nacional, Tegucigalpa | E20: 14.102994 | F20: -87.187926 | G20: =IF(ISBLANK(Events!F20), "", Events!F20) -> n4 | H20: =IF(ISBLANK(Events!G20), "", Events!G20) -> c4 | I20: =IF(ISBLANK(Events!H20), "", Events!H20) -> src19
A21: =Events!A21 -> National Jurisdiction Judge Lizeth Vallecillo issues a ruling that links the nine environmental defenders to crimes of aggravated arson and unjust deprivation of liberty, while dismissing the crimes of illicit association and theft. They are subsequently placed in pretrial detention in Olanchito. | B21: =TEXT(Events!B21, "MM/DD/YYYY") -> 09/01/2019 | D21: =Events!E21 -> Tocoa | E21: 14.102994 | F21: -87.187926 | G21: =IF(ISBLANK(Events!F21), "", Events!F21) -> n4 | H21: =IF(ISBLANK(Events!G21), "", Events!G21) -> c4 | I21: =IF(ISBLANK(Events!H21), "", Events!H21) -> src20
A22: =Events!A22 -> The National Jurisdiction Court of Appeals rejects a habeas corpus petition filed by the defence attorney. In response, prominent international advocacy organizations, including the Due Process of Law Foundation (DPLF), Human Rights Research and Education Centre, and the Collective Corporation of Lawyers “José Alvear Restrepo” filed a joint amicus brief echoing the defense attorneys ’previously expressed concerns and asserting that the community leaders ’detention was in violation of both domestic and international law. | B22: =TEXT(Events!B22, "MM/DD/YYYY") -> 09/25/2019 | D22: =Events!E22 -> Juzgado de Jurisdicción Nacional, Tegucigalpa | E22: 14.102994 | F22: -87.187926 | G22: =IF(ISBLANK(Events!F22), "", Events!F22) -> n4 | H22: =IF(ISBLANK(Events!G22), "", Events!G22) -> c4 | I22: =IF(ISBLANK(Events!H22), "", Events!H22) -> src21
A23: =Events!A23 -> Following another hearing, the decision is made to extend the pretrial detention of the Guapinol activists. | B23: =TEXT(Events!B23, "MM/DD/YYYY") -> 11/06/2019 | D23: =Events!E23 -> Centro Penal, Olanchito | E23: 14.102994 | F23: -87.187926 | G23: =IF(ISBLANK(Events!F23), "", Events!F23) -> n4 | H23: =IF(ISBLANK(Events!G23), "", Events!G23) -> c4 | I23: =IF(ISBLANK(Events!H23), "", Events!H23) -> src22
A24: =Events!A24 -> A series of break-ins are reported at the Tocoa office of the Coordinadora de Organizaciones Populares del Aguán (COPA), a conglomerate of organisations defending human, enviornmental, and social rights in the Aguan Valley Region. Unidentified individuals stole a computer and printer and ransacked drawers filled with documents. COPA member Carlos Leonel George reported the incident to the police. Rather than investigate the break-ins, the police arrest Carlos, who was one of the twelve Guapinol community members who voluntarily went to court in February 2019, only to have all the charges subsequently dismissed. | B24: =TEXT(Events!B24, "MM/DD/YYYY") -> 12/01/2019 | D24: =Events!E24 -> Tocoa | G24: =IF(ISBLANK(Events!F24), "", Events!F24) -> n3 | H24: =IF(ISBLANK(Events!G24), "", Events!G24) -> c3 | I24: =IF(ISBLANK(Events!H24), "", Events!H24) -> src23
A25: =Events!A25 -> The Center for International Justice and Law (CEJIL) submits an amicus brief to the National Jurisdiction Court of Appeals. | B25: =TEXT(Events!B25, "MM/DD/YYYY") -> 02/27/2020 | D25: =Events!E25 | G25: =IF(ISBLANK(Events!F25), "", Events!F25) -> n4 | H25: =IF(ISBLANK(Events!G25), "", Events!G25) -> c5 | I25: =IF(ISBLANK(Events!H25), "", Events!H25) -> src24
A26: =Events!A26 -> A group of civil society organizations, including the National Committee against Torture and Cruel, Inhumane, and Degrading Treatment (MNP-CONAPREV) and the Committee for Family of the Detained and Disappeared (COFADEH), amongst others, file a second habeas corpus petition with the Supreme Court of Honduras. | B26: =TEXT(Events!B26, "MM/DD/YYYY") -> 03/24/2020 | D26: =Events!E26 | G26: =IF(ISBLANK(Events!F26), "", Events!F26) -> n4 | H26: =IF(ISBLANK(Events!G26), "", Events!G26) -> c5 | I26: =IF(ISBLANK(Events!H26), "", Events!H26) -> src25
A27: =Events!A27 -> In Tegucigalpa, the National Jurisdiction Court of Appeals a dismissal previously issued in favour of human rights defenders Juan Antonio López, Carlos Leonel George, Reinaldo Domínguez, José Adalid Cedillo and Marco Tulio Ramos. | B27: =TEXT(Events!B27, "MM/DD/YYYY") -> 08/13/2020 | D27: =Events!E27 -> Juzgado de Jurisdicción Nacional, Tegucigalpa | E27: 14.102994 | F27: -87.187926 | G27: =IF(ISBLANK(Events!F27), "", Events!F27) -> n4 | H27: =IF(ISBLANK(Events!G27), "", Events!G27) -> c4 | I27: =IF(ISBLANK(Events!H27), "", Events!H27) -> src26
A28: =Events!A28 -> The Honduran Human Rights Ombudsperson writes a public letter directed at the judicial authorities which describes the detained members of the CMDBCP as human rights activists engaged in legitimate protest activities. | B28: =TEXT(Events!B28, "MM/DD/YYYY") -> 09/22/2020 | D28: =Events!E28 | G28: =IF(ISBLANK(Events!F28), "", Events!F28) -> n4 | H28: =IF(ISBLANK(Events!G28), "", Events!G28) -> c5 | I28: =IF(ISBLANK(Events!H28), "", Events!H28) -> src27
A29: =Events!A29 -> Joaquin Morazan Erazo, named in the 2018 arrest warrant, is shot and killed at his home in Tocoa, Colon. | B29: =TEXT(Events!B29, "MM/DD/YYYY") -> 10/13/2020 | D29: =Events!E29 -> Tocoa | E29: 15.657623 | F29: -85.997824 | G29: =IF(ISBLANK(Events!F29), "", Events!F29) -> n3 | H29: =IF(ISBLANK(Events!G29), "", Events!G29) -> c3 | I29: =IF(ISBLANK(Events!H29), "", Events!H29) -> src28
A30: =Events!A30 -> The Office of the United Nations High Commissioner for Human Rights (UN OHCHR) issues a country report raising concerns about the misuse of the judicial system in the Guapinol case. | B30: =TEXT(Events!B30, "MM/DD/YYYY") -> 02/25/2021 | D30: =Events!E30 | G30: =IF(ISBLANK(Events!F30), "", Events!F30) -> n4 | H30: =IF(ISBLANK(Events!G30), "", Events!G30) -> c5 | I30: =IF(ISBLANK(Events!H30), "", Events!H30) -> src29
A31: =Events!A31 -> The UN Working Group on Arbitrary Detention declares the Guapinol Eight - Porfirio Sorto Cedillo, José Abelino Cedillo, Kelvin Alejandro Romero, Arnol Javier Alemán, Ever Alexander Cedillo, Orbin Nahún Hernández, and Daniel Márquez - to be arbitrarily detained and calls for their release. | B31: =TEXT(Events!B31, "MM/DD/YYYY") -> 03/03/2021 | D31: =Events!E31 | G31: =IF(ISBLANK(Events!F31), "", Events!F31) -> n4 | H31: =IF(ISBLANK(Events!G31), "", Events!G31) -> c5 | I31: =IF(ISBLANK(Events!H31), "", Events!H31) -> src30
A32: =Events!A32 -> Members of the CMDBPC present an environmental report to the Secretariat of Natural Resources and Environment containing evidence that mining activity and related road infrastructure in the Carlos Escaleras Mejia National Park has negatively impacted 35 micro-basins of the Guapinol and San Pedro rivers. | B32: =TEXT(Events!B32, "MM/DD/YYYY") -> 06/27/2021 | D32: =Events!E32 -> ASP Mining Concession, Montaña de Botaderos National Park | G32: =IF(ISBLANK(Events!F32), "", Events!F32) -> n2 | H32: =IF(ISBLANK(Events!G32), "", Events!G32) -> c7 | I32: =IF(ISBLANK(Events!H32), "", Events!H32) -> src52
A33: =Events!A33 -> The preventive detention of the Guapinol Eight is extended for an six additional months. | B33: =TEXT(Events!B33, "MM/DD/YYYY") -> 08/26/2021 | D33: =Events!E33 -> Centro Penal, Olanchito | G33: =IF(ISBLANK(Events!F33), "", Events!F33) -> n4 | H33: =IF(ISBLANK(Events!G33), "", Events!G33) -> c4 | I33: =IF(ISBLANK(Events!H33), "", Events!H33) -> src31
A34: =Events!A34 -> The trial against the Guapinol Eight begins after over two years of pre-trial detention. | B34: =TEXT(Events!B34, "MM/DD/YYYY") -> 12/01/2021 | D34: =Events!E34 -> Juzgado de Letra, Trujillo | G34: =IF(ISBLANK(Events!F34), "", Events!F34) -> n4 | H34: =IF(ISBLANK(Events!G34), "", Events!G34) -> c4 | I34: =IF(ISBLANK(Events!H34), "", Events!H34) -> src32
A35: =Events!A35 -> Amnesty International writes an open letter expressing concerns about irregularities in the prosecution of the Guapinol Eight and describing those standing trial as 'victims of arbitrary detention and unfounded criminal prosecution stemming solely from their human rights work.' | B35: =TEXT(Events!B35, "MM/DD/YYYY") -> 12/11/2021 | D35: =Events!E35 | G35: =IF(ISBLANK(Events!F35), "", Events!F35) -> n4 | H35: =IF(ISBLANK(Events!G35), "", Events!G35) -> c5 | I35: =IF(ISBLANK(Events!H35), "", Events!H35) -> src33
A36: =Events!A36 -> A court in Trujillo finds six of the Guapinol Eight guilty of several charges including illegal deprivation of liberty and aggravated damages against a contractor of Inversiones Los Pinares, and aggravated damages against the company itself. | B36: =TEXT(Events!B36, "MM/DD/YYYY") -> 02/09/2022 | D36: =Events!E36 -> Juzgado de Letra, Trujillo | G36: =IF(ISBLANK(Events!F36), "", Events!F36) -> n4 | H36: =IF(ISBLANK(Events!G36), "", Events!G36) -> c4 | I36: =IF(ISBLANK(Events!H36), "", Events!H36) -> src34
A37: =Events!A37 -> One day after the sentencing, the Supreme Court declares a mistrial and grants injunctions in favour of the Guapinol Eight. | B37: =TEXT(Events!B37, "MM/DD/YYYY") -> 02/10/2022 | D37: =Events!E37 -> Corte Suprema de Justicia, Tegucigalpa | E37: 14.072813 | F37: -87.200923 | G37: =IF(ISBLANK(Events!F37), "", Events!F37) -> n4 | H37: =IF(ISBLANK(Events!G37), "", Events!G37) -> c4 | I37: =IF(ISBLANK(Events!H37), "", Events!H37) -> src35
A38: =Events!A38 -> Environmental rights defenders José Daniel Márquez, José Abelino Cedillo, Ewer Cedillo, Kelvin Romero, Orbin Nahún Hernández and Porfirio Soto, are released on bail after 914 days spent in pre-trial detention. | B38: =TEXT(Events!B38, "MM/DD/YYYY") -> 02/25/2022 | D38: =Events!E38 -> Centro Penal, Olanchito | G38: =IF(ISBLANK(Events!F38), "", Events!F38) -> n4 | H38: =IF(ISBLANK(Events!G38), "", Events!G38) -> c4 | I38: =IF(ISBLANK(Events!H38), "", Events!H38) -> src36
A39: =Events!A41 -> Aly Magdaleno Domínguez Ramos and Jairo Bonilla Ayala, two residents criminalised for their opposition to the mining project, are murdered in Guapinol. | B39: =TEXT(Events!B41, "MM/DD/YYYY") -> 01/07/2023 | D39: =Events!E41 -> Guapinol | E39: 15.615514 | F39: -86.038033 | G39: =IF(ISBLANK(Events!F41), "", Events!F41) -> n3 | H39: =IF(ISBLANK(Events!G41), "", Events!G41) -> c3 | I39: =IF(ISBLANK(Events!H41), "", Events!H41) -> src37
A40: =Events!A42 -> Six activists discover they may still face criminal prosecution as a result of an appeal by the Prosecutor's office. | B40: =TEXT(Events!B42, "MM/DD/YYYY") -> 02/07/2023 | D40: =Events!E42 | G40: =IF(ISBLANK(Events!F42), "", Events!F42) -> n4 | H40: =IF(ISBLANK(Events!G42), "", Events!G42) -> c4 | I40: =IF(ISBLANK(Events!H42), "", Events!H42) -> src38
...

Sheet EXPORT_SOURCES
A1: id | B1: title | C1: thumbnail | D1: description | E1: path1 | F1: path2 | G1: path3 | H1: type
A2: =Sources!A2 -> src1 | B2: =Sources!B2 -> Honduran Government Enacts New General Mining Law | C2: =IF(ISBLANK(Sources!C2), "", CONCAT("images/", Sources!C2)) | D2: =Sources!D2 | E2: =IF(ISBLANK(Sources!E2), "", CONCAT("", Sources!E2)) | F2: =IF(ISBLANK(Sources!F2), "", CONCAT("", Sources!F2)) | G2: =IF(ISBLANK(Sources!G2), "", CONCAT("", Sources!G2))
A3: =Sources!A3 -> src2 | B3: =Sources!B3 -> Honduras Reduces Carlos Escaleras Mejía National Park Protected Area | C3: =IF(ISBLANK(Sources!C3), "", CONCAT("images/", Sources!C3)) | D3: =Sources!D3 | E3: =IF(ISBLANK(Sources!E3), "", CONCAT("", Sources!E3)) -> images/231213.png | F3: =IF(ISBLANK(Sources!F3), "", CONCAT("", Sources!F3)) | G3: =IF(ISBLANK(Sources!G3), "", CONCAT("", Sources!G3))
A4: =Sources!A4 -> src3 | B4: =Sources!B4 -> Los Pinares Granted Mining License in National Park | C4: =IF(ISBLANK(Sources!C4), "", CONCAT("images/", Sources!C4)) | D4: =Sources!D4 | E4: =IF(ISBLANK(Sources!E4), "", CONCAT("", Sources!E4)) -> images/28012014.png | F4: =IF(ISBLANK(Sources!F4), "", CONCAT("", Sources!F4)) | G4: =IF(ISBLANK(Sources!G4), "", CONCAT("", Sources!G4))
A5: =Sources!A5 -> src4 | B5: =Sources!B5 -> ECOTEK Obtains License for Iron Pelletizing Plant | C5: =IF(ISBLANK(Sources!C5), "", CONCAT("images/", Sources!C5)) | D5: =Sources!D5 | E5: =IF(ISBLANK(Sources!E5), "", CONCAT("", Sources!E5)) | F5: =IF(ISBLANK(Sources!F5), "", CONCAT("", Sources!F5)) | G5: =IF(ISBLANK(Sources!G5), "", CONCAT("", Sources!G5))
A6: =Sources!A6 -> src5 | B6: =Sources!B6 -> Guapinol River Contamination Documented by Residents | C6: =IF(ISBLANK(Sources!C6), "", CONCAT("images/", Sources!C6)) | D6: =Sources!D6 | E6: =IF(ISBLANK(Sources!E6), "", CONCAT("", Sources!E6)) -> images/26042018.jpg | F6: =IF(ISBLANK(Sources!F6), "", CONCAT("", Sources!F6)) -> images/26042018a.jpg | G6: =IF(ISBLANK(Sources!G6), "", CONCAT("", Sources!G6)) -> images/26042018b.jpg
A7: =Sources!A7 -> src6 | B7: =Sources!B7 -> Community Meeting Organized to Discuss Mining Project | C7: =IF(ISBLANK(Sources!C7), "", CONCAT("images/", Sources!C7)) | D7: =Sources!D7 | E7: =IF(ISBLANK(Sources!E7), "", CONCAT("", Sources!E7)) -> images/07052018.jpg | F7: =IF(ISBLANK(Sources!F7), "", CONCAT("", Sources!F7)) | G7: =IF(ISBLANK(Sources!G7), "", CONCAT("", Sources!G7))
A8: =Sources!A8 -> src7 | B8: =Sources!B8 -> Peaceful Demonstration at Caja Rural | C8: =IF(ISBLANK(Sources!C8), "", CONCAT("images/", Sources!C8)) | D8: =Sources!D8 | E8: =IF(ISBLANK(Sources!E8), "", CONCAT("", Sources!E8)) -> images/10052018.jpg | F8: =IF(ISBLANK(Sources!F8), "", CONCAT("", Sources!F8)) -> images/10052018a.jpg | G8: =IF(ISBLANK(Sources!G8), "", CONCAT("", Sources!G8)) -> images/10052018b.jpg
A9: =Sources!A9 -> src8 | B9: =Sources!B9 -> Further River Contamination Evidence Circulated | C9: =IF(ISBLANK(Sources!C9), "", CONCAT("images/", Sources!C9)) | D9: =Sources!D9 | E9: =IF(ISBLANK(Sources!E9), "", CONCAT("", Sources!E9)) -> images/30072018.jpg | F9: =IF(ISBLANK(Sources!F9), "", CONCAT("", Sources!F9)) -> images/30072018a.mp4 | G9: =IF(ISBLANK(Sources!G9), "", CONCAT("", Sources!G9))
A10: =Sources!A10 -> src9 | B10: =Sources!B10 -> Guapinol Encampment Established to Defend Water | C10: =IF(ISBLANK(Sources!C10), "", CONCAT("images/", Sources!C10)) | D10: =Sources!D10 | E10: =IF(ISBLANK(Sources!E10), "", CONCAT("", Sources!E10)) -> images/01082018.jpg | F10: =IF(ISBLANK(Sources!F10), "", CONCAT("", Sources!F10)) -> images/01082018a.jpg | G10: =IF(ISBLANK(Sources!G10), "", CONCAT("", Sources!G10)) -> images/01082018b.jpg
A11: =Sources!A11 -> src10 | B11: =Sources!B11 -> Security Official Shoots Protester During Dispute | C11: =IF(ISBLANK(Sources!C11), "", CONCAT("images/", Sources!C11)) | D11: =Sources!D11 | E11: =IF(ISBLANK(Sources!E11), "", CONCAT("", Sources!E11)) -> images/07092018.jpg | F11: =IF(ISBLANK(Sources!F11), "", CONCAT("", Sources!F11)) | G11: =IF(ISBLANK(Sources!G11), "", CONCAT("", Sources!G11))
A12: =Sources!A12 -> src11 | B12: =Sources!B12 -> Arrest Warrants Issued for Eighteen Community Members | C12: =IF(ISBLANK(Sources!C12), "", CONCAT("images/", Sources!C12)) | D12: =Sources!D12 | E12: =IF(ISBLANK(Sources!E12), "", CONCAT("", Sources!E12)) | F12: =IF(ISBLANK(Sources!F12), "", CONCAT("", Sources!F12)) | G12: =IF(ISBLANK(Sources!G12), "", CONCAT("", Sources!G12))
A13: =Sources!A13 -> src12 | B13: =Sources!B13 -> Police and Military Evict Encampment with Violence | C13: =IF(ISBLANK(Sources!C13), "", CONCAT("images/", Sources!C13)) | D13: =Sources!D13 | E13: =IF(ISBLANK(Sources!F13), "", CONCAT("", Sources!F13)) -> images/27102018a.mp4 | F13: =IF(ISBLANK(Sources!E13), "", CONCAT("", Sources!E13)) -> images/27102018.jpg | G13: =IF(ISBLANK(Sources!G13), "", CONCAT("", Sources!G13))
A14: =Sources!A14 -> src13 | B14: =Sources!B14 -> Thirteen Community Members Appear Before Court | C14: =IF(ISBLANK(Sources!C14), "", CONCAT("images/", Sources!C14)) | D14: =Sources!D14 | E14: =IF(ISBLANK(Sources!E14), "", CONCAT("", Sources!E14)) | G14: =IF(ISBLANK(Sources!G14), "", CONCAT("", Sources!G14))
A15: =Sources!A15 -> src14 | B15: =Sources!B15 -> Constitutional Challenge Filed Against Decree 252-2013 | C15: =IF(ISBLANK(Sources!C15), "", CONCAT("images/", Sources!C15)) | D15: =Sources!D15 | E15: =IF(ISBLANK(Sources!E15), "", CONCAT("", Sources!E15)) | F15: =IF(ISBLANK(Sources!F15), "", CONCAT("", Sources!F15)) | G15: =IF(ISBLANK(Sources!G15), "", CONCAT("", Sources!G15))
A16: =Sources!A16 -> src15 | B16: =Sources!B16 -> Charges Dismissed Against Thirteen Defenders | C16: =IF(ISBLANK(Sources!C16), "", CONCAT("images/", Sources!C16)) | D16: =Sources!D16 | E16: =IF(ISBLANK(Sources!E16), "", CONCAT("", Sources!E16)) | F16: =IF(ISBLANK(Sources!F16), "", CONCAT("", Sources!F16)) | G16: =IF(ISBLANK(Sources!G16), "", CONCAT("", Sources!G16))
A17: =Sources!A17 -> src16 | B17: =Sources!B17 -> Detained Protesters Released | C17: =IF(ISBLANK(Sources!C17), "", CONCAT("images/", Sources!C17)) | D17: =Sources!D17 | E17: =IF(ISBLANK(Sources!E17), "", CONCAT("", Sources!E17)) -> images/06032019.jpg | F17: =IF(ISBLANK(Sources!F17), "", CONCAT("", Sources!F17)) | G17: =IF(ISBLANK(Sources!G17), "", CONCAT("", Sources!G17))
A18: =Sources!A18 -> src17 | B18: =Sources!B18 -> Seven Additional Community Members Appear in Court | C18: =IF(ISBLANK(Sources!C18), "", CONCAT("images/", Sources!C18)) | D18: =Sources!D18 | E18: =IF(ISBLANK(Sources!E18), "", CONCAT("", Sources!E18)) -> images/26082019.mp4 | F18: =IF(ISBLANK(Sources!F18), "", CONCAT("", Sources!F18)) | G18: =IF(ISBLANK(Sources!G18), "", CONCAT("", Sources!G18))
A19: =Sources!A19 -> src18 | B19: =Sources!B19 -> Environmental Defender Roberto Argueta Assassinated | C19: =IF(ISBLANK(Sources!C19), "", CONCAT("images/", Sources!C19)) | D19: =Sources!D19 | E19: =IF(ISBLANK(Sources!E19), "", CONCAT("", Sources!E19)) -> images/28082019.jpg | F19: =IF(ISBLANK(Sources!F19), "", CONCAT("", Sources!F19)) | G19: =IF(ISBLANK(Sources!G19), "", CONCAT("", Sources!G19))
A20: =Sources!A20 -> src19 | B20: =Sources!B20 -> Temporary Dismissal Granted to Arnold Alemán | C20: =IF(ISBLANK(Sources!C20), "", CONCAT("images/", Sources!C20)) | D20: =Sources!D20 | E20: =IF(ISBLANK(Sources!E20), "", CONCAT("", Sources!E20)) | F20: =IF(ISBLANK(Sources!F20), "", CONCAT("", Sources!F20)) | G20: =IF(ISBLANK(Sources!G20), "", CONCAT("", Sources!G20))
A21: =Sources!A21 -> src20 | B21: =Sources!B21 -> Nine Environmental Defenders Placed in Pretrial Detention | C21: =IF(ISBLANK(Sources!C21), "", CONCAT("images/", Sources!C21)) | D21: =Sources!D21 | E21: =IF(ISBLANK(Sources!E21), "", CONCAT("", Sources!E21)) -> images/01092019.mp4 | F21: =IF(ISBLANK(Sources!F21), "", CONCAT("", Sources!F21)) | G21: =IF(ISBLANK(Sources!G21), "", CONCAT("", Sources!G21))
A22: =Sources!A22 -> src21 | B22: =Sources!B22 -> Court Rejects Habeas Corpus Petition | C22: =IF(ISBLANK(Sources!C22), "", CONCAT("images/", Sources!C22)) | D22: =Sources!D22 | E22: =IF(ISBLANK(Sources!E22), "", CONCAT("", Sources!E22)) | F22: =IF(ISBLANK(Sources!F22), "", CONCAT("", Sources!F22)) | G22: =IF(ISBLANK(Sources!G22), "", CONCAT("", Sources!G22))
A23: =Sources!A23 -> src22 | B23: =Sources!B23 -> Pretrial Detention Extended for Guapinol Activists | C23: =IF(ISBLANK(Sources!C23), "", CONCAT("images/", Sources!C23)) | D23: =Sources!D23 | E23: =IF(ISBLANK(Sources!E23), "", CONCAT("", Sources!E23)) | F23: =IF(ISBLANK(Sources!F23), "", CONCAT("", Sources!F23)) | G23: =IF(ISBLANK(Sources!G23), "", CONCAT("", Sources!G23))
A24: =Sources!A24 -> src23 | B24: =Sources!B24 -> Break-ins Reported at COPA Office | C24: =IF(ISBLANK(Sources!C24), "", CONCAT("images/", Sources!C24)) | D24: =Sources!D24 | E24: =IF(ISBLANK(Sources!E24), "", CONCAT("", Sources!E24)) | F24: =IF(ISBLANK(Sources!F24), "", CONCAT("", Sources!F24)) | G24: =IF(ISBLANK(Sources!G24), "", CONCAT("", Sources!G24))
A25: =Sources!A25 -> src24 | B25: =Sources!B25 -> CEJIL Submits Amicus Brief to Court of Appeals | C25: =IF(ISBLANK(Sources!C25), "", CONCAT("images/", Sources!C25)) | D25: =Sources!D25 | E25: =IF(ISBLANK(Sources!E25), "", CONCAT("", Sources!E25)) | F25: =IF(ISBLANK(Sources!F25), "", CONCAT("", Sources!F25)) | G25: =IF(ISBLANK(Sources!G25), "", CONCAT("", Sources!G25))
A26: =Sources!A26 -> src25 | B26: =Sources!B26 -> Second Habeas Corpus Petition Filed with Supreme Court | C26: =IF(ISBLANK(Sources!C26), "", CONCAT("images/", Sources!C26)) | D26: =Sources!D26 | E26: =IF(ISBLANK(Sources!E26), "", CONCAT("", Sources!E26)) | F26: =IF(ISBLANK(Sources!F26), "", CONCAT("", Sources!F26)) | G26: =IF(ISBLANK(Sources!G26), "", CONCAT("", Sources!G26))
... A53: =Sources!A53 -> src52 | B53: =Sources!B53 -> Los Pinares Executives Charged with Illegal Exploitation and Aggravated Damages | C53: =IF(ISBLANK(Sources!C53), "", CONCAT("images/", Sources!C53)) | D53: =Sources!D53 | E53: =IF(ISBLANK(Sources!E53), "", CONCAT("", Sources!E53)) | F53: =IF(ISBLANK(Sources!F53), "", CONCAT("", Sources!F53)) | G53: =IF(ISBLANK(Sources!G53), "", CONCAT("", Sources!G53))

Sheet EXPORT_ASSOCIATIONS
A1: id | B1: title | C1: desc | D1: mode | E1: filter_path0 | F1: filter_path1 | G1: filter_path2
A2: =Associations!A2 -> n1 | B2: =Associations!B2 -> Origins of the situation | C2: =Associations!B2 -> Origins of the situation | D2: =Associations!C2 -> NARRATIVE | E2: =Associations!D2 | F2: =Associations!E2 | G2: =Associations!F2
A3: =Associations!A3 -> n2 | B3: =Associations!B3 -> Community resistance to the Los Pinares-ECOTEK project | C3: =Associations!B3 -> Community resistance to the Los Pinares-ECOTEK project | D3: =Associations!C3 -> NARRATIVE | E3: =Associations!D3 | F3: =Associations!E3
A4: =Associations!A4 -> n3 | B4: =Associations!B4 -> The use of violence against the environmental defenders | C4: =Associations!B4 -> The use of violence against the environmental defenders | D4: =Associations!C4 -> NARRATIVE | E4: =Associations!D4 | F4: =Associations!E4
A5: =Associations!A5 -> n4 | B5: =Associations!B5 -> The criminalisation of environmental defenders | C5: =Associations!B5 -> The criminalisation of environmental defenders | D5: =Associations!C5 -> NARRATIVE | E5: =Associations!D5 | F5: =Associations!E5
A6: =Associations!A8 -> c1 | B6: =Associations!B8 -> Policy and regulatory changes | C6: =Associations!B8 -> Policy and regulatory changes | D6: =Associations!C8 -> CATEGORY | E6: =Associations!D8 | F6: =Associations!E8
A7: =Associations!A9 -> c2 | B7: =Associations!B9 -> Peaceful protests and activism | C7: =Associations!B9 -> Peaceful protests and activism | D7: =Associations!C9 -> CATEGORY | E7: =Associations!D9 | F7: =Associations!E9
A8: =Associations!A10 -> c3 | B8: =Associations!B10 -> Violence and conflict | C8: =Associations!B10 -> Violence and conflict | D8: =Associations!C10 -> CATEGORY | E8: =Associations!D10 | F8: =Associations!E10
A9: =Associations!A11 -> c4 | B9: =Associations!B11 -> Legal proceedings | C9: =Associations!B11 -> Legal proceedings | D9: =Associations!C11 -> CATEGORY | E9: =Associations!D11 | F9: =Associations!E11
A10: =Associations!A12 -> c5 | B10: =Associations!B12 -> National and international advocacy | C10: =Associations!B12 -> National and international advocacy | D10: =Associations!C12 -> CATEGORY | E10: =Associations!D12 | F10: =Associations!E12
A11: =Associations!A13 -> c6 | B11: =Associations!B13 -> Developments in the Los Pinares-ECOTEK project | C11: =Associations!B13 -> Developments in the Los Pinares-ECOTEK project | D11: =Associations!C13 -> CATEGORY | E11: =Associations!D13 | F11: =Associations!E13
